I'm sorry, but an uncaught exception occurred.

While running game code:
  File "game/chapter1.rpy", line 50, in script
    urk happy "АХАХАХАХАХ, ТЫ ТАК МНОГО РАЗ УМЕР, КАКОЙ ТЫ ЖАЛКИЙ"
Exception: Sayer 'urk' is not defined.

-- Full Traceback ------------------------------------------------------------

Full traceback:
  File "game/chapter1.rpy", line 50, in script
    urk happy "АХАХАХАХАХ, ТЫ ТАК МНОГО РАЗ УМЕР, КАКОЙ ТЫ ЖАЛКИЙ"
  File "C:\Prog\Renpy\renpy-8.3.3-sdk\renpy\ast.py", line 2573, in execute
    Say.execute(self)
  File "C:\Prog\Renpy\renpy-8.3.3-sdk\renpy\ast.py", line 575, in execute
    who = eval_who(self.who, self.who_fast)
  File "C:\Prog\Renpy\renpy-8.3.3-sdk\renpy\ast.py", line 464, in eval_who
    raise Exception("Sayer '%s' is not defined." % who)
Exception: Sayer 'urk' is not defined.

Windows-10-10.0.26100 AMD64
Ren'Py 8.3.3.24111502
Исповедь Анархиста 1.0
Sun Dec 29 21:58:34 2024
